<?xml version="1.0" ?> <!-- define the version (xml file)-->
<sdf version="1.8"> 
    <world name="ship_world"> <!-- define the world name-->
        <light type="directional" name="sun"> <!-- light of the world-->
            <cast_shadows>true</cast_shadows> 
            <pose>0 0 10 0 0 0</pose> <!-- position: 10 meters on z axis-->
            <diffuse>0.8 0.8 0.8 1</diffuse> <!-- diffuse light -->
            <specular>0.2 0.2 0.2 1</specular> <!-- specular reflex-->
            <direction>-0.5 0.1 -0.9</direction> <!-- direction of the light-->
        </light>

        <gravity>0 0 -9.81</gravity> <!-- add gravity (9.81 in z direction)-->

        <physics name="bullet_physics" type="bullet">
            <max_step_size>0.001</max_step_size>
            <real_time_factor>1.0</real_time_factor>
            <bullet>
                <solver>
                    <type>sequential_impulse</type>
                </solver>
            </bullet>
        </physics>

        <!--inside the world we can add multiple models-->
        <model name="ship_corridor_dynamic"> <!--define the model ship_corridor-->
            <static>false</static> <!-- static false because we want the world subjec to physics-->
            
            <!-- 
            !! kinematic chain of the corridor !! 

            4 link connected by joints, to simulate the dynamics of the ship
            world - fixed
                -> world_base_link
                    ->revolute ROLL (around x)
                        ->roll_link
                            ->revolute PITCH (around y)
                                ->pitch_link
                                    ->prismatic HEAVE (along z)
                                        ->CoG_link (Center_of_Gravity)
                                            ->fixed joint
                                                ->room_link 
            -->

            <!-- define the world base link (fixed wrt the world)-->
            <link name="world_base_link"> 
                <pose>0 0 0 0 0 0 </pose>
                <inertial> <!--every link should have an inertia, even if it's a reference link-->
                    <mass>1.0</mass> <!-- we set its mass to one-->
                    <inertia>
                        <ixx>0.1</ixx> 
                        <iyy>0.1</iyy>
                        <izz>0.1</izz>
                    </inertia>
                </inertial>
            </link>
            <joint name="world_fixed_joint" type="fixed">  <!-- fix the link (world_base_link) to the gazebo floor (world)-->
                <parent>world</parent>
                <child>world_base_link</child>
            </joint>

            <!-- link to simulate rolling of the CoG-->
            <link name="roll_link"> <!--every link should have an inertia, even if it's a reference link-->
                <inertial>
                    <mass>1.0</mass> 
                    <inertia>
                        <ixx>0.1</ixx> 
                        <iyy>0.1</iyy>
                        <izz>0.1</izz>
                    </inertia>
                </inertial>
            </link>
            <!-- create a joint between the world link and the roll link-->
            <!-- of the type: revolute, on x axis-->
            <joint name="roll_joint" type="revolute">
                <parent>world_base_link</parent> <!-- i-1 link connected to the joint (the fixed link)-->
                <child>roll_link</child> <!-- i link connected to the joint (the rotating link)--> 
                <axis>
                    <xyz>1 0 0</xyz> <!-- roll, revolute around x axis-->
                    <limit> <!-- boundaries of roll (radiant)-->
                        <lower>-0.5</lower> 
                        <upper>0.5</upper>
                    </limit>
                    <dynamics><damping>10.0</damping><friction>5.0</friction></dynamics>
                </axis>
            </joint>

            <link name="pitch_link">
                <inertial>
                    <mass>1.0</mass>
                    <inertia>
                        <ixx>0.1</ixx>
                        <iyy>0.1</iyy>
                        <izz>0.1</izz>
                    </inertia>
                </inertial>
            </link>

            <joint name="pitch_joint" type="revolute">
                <parent>roll_link</parent>
                <child>pitch_link</child>
                <axis>
                    <xyz>0 1 0</xyz> <!-- pitch, revolute around y axis-->
                    <limit> <!-- boundaries of pitch (radiant)-->
                        <lower>-0.2</lower> 
                        <upper>0.2</upper>
                    </limit>
                    <dynamics><damping>10.0</damping><friction>5.0</friction></dynamics>
                </axis>
            </joint>

            <link name="CoG_link">
                <pose>0 0 5 0 0 0</pose> <!-- put the CoG 5 meters over the zero axis-->
                <inertial>
                    <mass>5000.0</mass> <!-- mass of the ship-->
                    <inertia>
                        <ixx>500.0</ixx> <!-- inertial matrix of the ship-->
                        <iyy>500.0</iyy>
                        <izz>500.0</izz>
                    </inertia>
                </inertial>
            </link>
            <joint name="heave_joint" type="prismatic">
                <parent>pitch_link</parent>
                <child>CoG_link</child>
                <axis>
                    <xyz>0 0 1</xyz>
                    <limit>
                        <lower>-2.0</lower>
                        <upper>2.0</upper>
                    </limit>
                    <dynamics><damping>10.0</damping><friction>5.0</friction></dynamics>
                </axis>
            </joint>
            
            <link name="corridor_link"> 
                <pose>10 0 0 0 0 1.5708</pose>
                <inertial>
                    <mass>5000.0</mass>
                    <inertia>
                        <ixx>500.0</ixx>
                        <iyy>500.0</iyy>
                        <izz>500.0</izz>
                    </inertia>
                </inertial>

                <visual name="corridor_visual"> 
                    <geometry>
                        <mesh>
                            <uri>file:///home/alienware/ship_ws/src/ship_gazebo/models/ship_corridor.dae</uri> 
                            <scale>1 1 1</scale> 
                        </mesh>
                    </geometry>
                </visual>

                <collision name="corridor_collision">
                    <geometry>
                        <mesh>
                            <uri>file:///home/alienware/ship_ws/src/ship_gazebo/models/ship_corridor.stl</uri> 
                            <scale>1 1 1</scale>
                        </mesh>
                    </geometry>
                    <surface>
                        <contact>
                            <collide_bitmask>0xffff</collide_bitmask>
                        </contact>
                        <friction>
                            <ode>
                                <mu>1.0</mu> <mu2>1.0</mu2>
                            </ode>
                        </friction>
                    </surface> 
                </collision>
            </link>

            <joint name="corridor_joint" type="fixed">
                <parent>CoG_link</parent>
                <child>corridor_link</child>
            </joint>

            <!--CMake aggiunge automaticamente il prefisso lib al nome ShipMotionPlugin-->
            <!--name="ship_gazebo::ShipMotionPlugin" deve corrispondere alla stringa in GZ_ADD_PLUGIN_ALIAS nel .cc-->
            <plugin 
                filename="libShipMotionPlugin.so" 
                name="ship_gazebo::ShipMotionPlugin">

                <!--roll-->
                <roll_amplitude>0.3</roll_amplitude>
                <roll_frequency>0.1</roll_frequency>
                <roll_phase>0.0</roll_phase>

                <!--pitch-->
                <pitch_amplitude>0.0</pitch_amplitude>
                <pitch_frequency>0.0</pitch_frequency>
                <pitch_phase>0.0</pitch_phase>

                <!--heave-->
                <heave_amplitude>0.0</heave_amplitude>
                <heave_frequency>0.0</heave_frequency>
                <heave_phase>0.0</heave_phase>
            </plugin>

        </model>

    </world>
</sdf>