             

<?xml version="1.0" ?>
<sdf version="1.8"> 

    <world name="ship_world"> 
        <light type="directional" name="sun"> 
            <cast_shadows>true</cast_shadows> 
            <pose>0 0 10 0 0 0</pose> 
            <diffuse>0.8 0.8 0.8 1</diffuse> 
            <specular>0.2 0.2 0.2 1</specular> 
            <direction>-0.5 0.1 -0.9</direction> 
        </light>

        <gravity>0 0 -9.81</gravity> 
        
        <physics name="default_physics" type="dart">
            <max_step_size>0.001</max_step_size>
            <real_time_factor>1.0</real_time_factor>
        </physics>
    
        <model name="ship_corridor_dynamic"> 
            <static>false</static> 
            
            <link name="world_base_link"> 
                <pose>0 0 0 0 0 0 </pose>
                <inertial> 
                    <mass>1.0</mass> 
                    <inertia>
                        <ixx>0.1</ixx> 
                        <iyy>0.1</iyy>
                        <izz>0.1</izz>
                    </inertia>
                </inertial>
            </link>
            
            <joint name="world_fixed_joint" type="fixed">  
                <parent>world</parent>
                <child>world_base_link</child>
            </joint>

            <link name="roll_link"> 
                <gravity>false</gravity>
                <inertial>
                    <mass>1.0</mass> 
                    <inertia>
                        <ixx>0.1</ixx> 
                        <iyy>0.1</iyy>
                        <izz>0.1</izz>
                    </inertia>
                </inertial>
            </link>

            <joint name="roll_joint" type="revolute">
                <parent>world_base_link</parent> 
                <child>roll_link</child> 
                <axis>
                    <xyz>0 1 0</xyz> 
                    <limit> 
                        <lower>-0.5</lower> 
                        <upper>0.5</upper>
                        <effort>10000000</effort>
                    </limit>
                    <dynamics>
                        <damping>10.0</damping>
                        <friction>5.0</friction>
                    </dynamics>
                </axis>
            </joint>

            <link name="pitch_link">
                <gravity>false</gravity>
                <inertial>
                    <mass>1.0</mass>
                    <inertia>
                        <ixx>0.1</ixx>
                        <iyy>0.1</iyy>
                        <izz>0.1</izz>
                    </inertia>
                </inertial>
            </link>

            <joint name="pitch_joint" type="revolute">
                <parent>roll_link</parent>
                <child>pitch_link</child>
                <axis>
                    <xyz>1 0 0</xyz> 
                    <limit> 
                        <lower>-0.2</lower> 
                        <upper>0.2</upper>
                        <effort>10000000</effort>
                    </limit>
                    <dynamics>
                        <damping>10.0</damping>
                        <friction>5.0</friction>
                    </dynamics>
                </axis>
            </joint>

            <link name="CoG_link">
                <pose>0.0 0.0 0.0 0.0 0.0 0.0</pose> 
                <gravity>false</gravity>
                <inertial>
                    <mass>1.0</mass> 
                    <inertia>
                        <ixx>1.0</ixx> 
                        <iyy>1.0</iyy>
                        <izz>1.0</izz>
                    </inertia>
                </inertial>

                <visual name ="ship_hull">
                    <geometry>
                        <box>
                            <size>20.0 150.0 10.0</size> 
                        </box>
                    </geometry>
                    <material>
                        <ambient>0.5 0.5 0.8 0.3</ambient> 
                        <diffuse>0.5 0.5 0.8 0.3</diffuse>
                    </material>
                </visual>
            
                <sensor name = "ship_imu" type="imu"> 
                    <pose>0.0 0.0 0.0 0.0 0.0 0.0</pose> 
                    <always_on>true</always_on> 
                    <update_rate>100.0</update_rate>
                    <visualize>false</visualize>
                    <imu> 
                        <angular_velocity>
                            <x>
                                <noise type="gaussian">
                                    <mean>0.0</mean>
                                    <stddev>0.0001</stddev>
                                    <bias_mean>0.0</bias_mean>
                                </noise>
                            </x>
                            <y>
                                <noise type ="gaussian">
                                    <mean>0.0</mean>
                                    <stddev>0.0001</stddev>
                                    <bias_mean>0.0</bias_mean>
                                </noise>
                            </y>
                            <z>
                                <noise type ="gaussian">
                                    <mean>0.0</mean>
                                    <stddev>0.0001</stddev>
                                    <bias_mean>0.0</bias_mean>
                                </noise>
                            </z>
                        </angular_velocity>
                        <linear_acceleration>
                            <x>
                                <noise type="gaussian">
                                    <mean>0.0</mean>
                                    <stddev>0.00186</stddev>
                                    <bias_mean>0.0</bias_mean>
                                </noise>
                            </x>
                            <y>
                                <noise type ="gaussian">
                                    <mean>0.0</mean>
                                    <stddev>0.00186</stddev>
                                    <bias_mean>0.0</bias_mean>
                                </noise>
                            </y>
                            <z>
                                <noise type ="gaussian">
                                    <mean>0.0</mean>
                                    <stddev>0.00186</stddev>
                                    <bias_mean>0.0</bias_mean>
                                </noise>
                            </z>
                        </linear_acceleration>
                    </imu>
                </sensor>
            </link>

            <joint name="heave_joint" type="prismatic">
                <parent>pitch_link</parent>
                <child>CoG_link</child>
                <axis>
                    <xyz>0 0 1</xyz>
                    <limit>
                        <lower>-2.0</lower>
                        <upper>2.0</upper>
                        <effort>10000000</effort>
                    </limit>
                    <dynamics>
                        <damping>10.0</damping>
                        <friction>5.0</friction>
                    </dynamics>
                </axis>
            </joint>
            
            <link name="corridor_link"> 
                <pose>5.078 40.69 2.945 0.0 0.0 0.0</pose>
                <gravity>false</gravity>
                <inertial>
                    <mass>1.0</mass>
                    <inertia>
                        <ixx>1.0</ixx> 
                        <iyy>1.0</iyy>
                        <izz>1.0</izz>
                    </inertia>
                </inertial>

                <visual name="corridor_visual"> 
                    <geometry>
                        <mesh>
                            <uri>file:///home/alienware/ship_ws/src/ship_gazebo/models/ship_corridor.dae</uri> 
                            <scale>0.31525 0.13719333333333333 0.3677</scale> 
                        </mesh>
                    </geometry>
                </visual>

                <collision name="corridor_collision">
                    <geometry>
                        <mesh>
                            <uri>file:///home/alienware/ship_ws/src/ship_gazebo/models/ship_corridor.stl</uri> 
                            <scale>0.31525 0.13719333333333333 0.3677</scale>
                        </mesh>
                    </geometry>
                    <surface>
                        <contact>
                            <collide_bitmask>0xffff</collide_bitmask>
                        </contact>
                        <friction>
                            <ode>
                                <mu>1.0</mu> <mu2>1.0</mu2>
                            </ode>
                        </friction>
                    </surface> 
                </collision>
            </link>

            <joint name="corridor_joint" type="fixed">
                <parent>CoG_link</parent>
                <child>corridor_link</child>
            </joint>

            <plugin 
                filename="libShipMotionPlugin.so" 
                name="ship_gazebo::ShipMotionPlugin">
                <roll_amplitude>0.3</roll_amplitude>
                <roll_frequency>0.1</roll_frequency>
                <roll_phase>0.0</roll_phase>
                <pitch_amplitude>0.0</pitch_amplitude>
                <pitch_frequency>0.0</pitch_frequency>
                <pitch_phase>0.0</pitch_phase>
                <heave_amplitude>0.0</heave_amplitude>
                <heave_frequency>0.0</heave_frequency>
                <heave_phase>0.0</heave_phase>
            </plugin>
        </model>

        <plugin
            filename="gz-sim-physics-system"
            name="gz::sim::systems::Physics">
        </plugin>

        <plugin
            filename="gz-sim-user-commands-system"
            name="gz::sim::systems::UserCommands">
        </plugin>

        <plugin
            filename="gz-sim-scene-broadcaster-system"
            name="gz::sim::systems::SceneBroadcaster">
        </plugin>

        <plugin 
            filename="gz-sim-sensors-system" 
            name="gz::sim::systems::Sensors">
            <render_engine>ogre2</render_engine>
        </plugin>

        <plugin 
            filename="gz-sim-imu-system" 
            name="gz::sim::systems::Imu">
        </plugin>
    
    </world>
</sdf>